Workbook

Sheet Input
A1: Deck
A2: Type | D2: Landgain | E2: =G2/B3 -> #DIV/0! | F2: Lands | G2: =A60 -> 0 | H2: Enchantments | I2: =Calculations!T54 -> 0
A3: Cards | B3: =A60+I60+R60 -> 0 | D3: avg mana | E3: =(SUM(K9:K59)+SUM(T9:T59))/(I60+R60) -> #DIV/0! | F3: Creatures | G3: =Calculations!U54 -> 0 | H3: Sorceries | I3: =Calculations!Q54 -> 0
F4: Artifacts | G4: =Calculations!S54 -> 0 | H4: Instants | I4: =Calculations!R54 -> 0
F5: Planeswalkers | G5: =Calculations!V54 -> 0
A7: Lands | K7: Spells | V7: Creatures
A8: Number | B8: Name | C8: Colorgain | I8: Number | J8: Name | K8: Manacost | L8: Precise Cost | Q8: Type | R8: Number | S8: Name | T8: Manacost | U8: Precise Cost | Z8: Type
A60: =SUM(A9:A59) -> 0 | I60: =SUM(I9:I59) -> 0 | R60: =SUM(R9:R59) -> 0

Sheet Calculations
A1: Lands | I1: Spells | X1: Hands | Y1: Mana | AG1: Mana Cost
A2: Color | B2: Green | C2: Red | D2: Blue | E2: White | F2: Black | G2: Colorless | I2: Color | J2: Green | K2: Red | L2: Blue | M2: White | N2: Black | O2: Colorless | P2: Type | Q2: Sorcery | R2: Instant | S2: Artifact | T2: Enchantment | U2: Creature | V2: Planeswalker | Y2: Green | Z2: Red | AA2: Blue | AB2: White | AC2: Black | AD2: Colorless | AF2: 0 | AG2: 1 | AH2: 2 | AI2: 3 | AJ2: 4 | AK2: 5 | AL2: 6 | AM2: 7 | AN2: 8 | AO2: 9 | AP2: 10 | AQ2: 11 | AR2: 12 | AS2: 13 | AT2: 14 | AU2: 15 | AV2: 16
B3: =(IF(Input!C9="Green",1,0)+IF(Input!D9="Green",1,0)+IF(Input!E9="Green",1,0)+IF(Input!F9="Green",1,0)+IF(Input!G9="Green",1,0)+IF(Input!H9="Green",1,0))*Input!A9 -> 0 | C3: =(IF(Input!C9="Red",1,0)+IF(Input!D9="Red",1,0)+IF(Input!E9="Red",1,0)+IF(Input!F9="Red",1,0)+IF(Input!G9="Red",1,0)+IF(Input!H9="Red",1,0))*Input!A9 -> 0 | D3: =(IF(Input!C9="Blue",1,0)+IF(Input!D9="Blue",1,0)+IF(Input!E9="Blue",1,0)+IF(Input!F9="Blue",1,0)+IF(Input!G9="Blue",1,0)+IF(Input!H9="Blue",1,0))*Input!A9 -> 0 | E3: =(IF(Input!C9="White",1,0)+IF(Input!D9="White",1,0)+IF(Input!E9="White",1,0)+IF(Input!F9="White",1,0)+IF(Input!G9="White",1,0)+IF(Input!H9="White",1,0))*Input!A9 -> 0 | F3: =(IF(Input!C9="Black",1,0)+IF(Input!D9="Black",1,0)+IF(Input!E9="Black",1,0)+IF(Input!F9="Black",1,0)+IF(Input!G9="Black",1,0)+IF(Input!H9="Black",1,0))*Input!A9 -> 0 | G3: =(IF(Input!C9="Colorless",1,0)+IF(Input!D9="Colorless",1,0)+IF(Input!E9="Colorless",1,0)+IF(Input!F9="Colorless",1,0)+IF(Input!G9="Colorless",1,0)+IF(Input!H9="Colorless",1,0))*Input!A9 -> 0 | J3: =(IF(Input!L9="Green",1,0)+IF(Input!M9="Green",1,0)+IF(Input!N9="Green",1,0)+IF(Input!O9="Green",1,0)+IF(Input!P9="Green",1,0))*Input!I9+(IF(Input!U9="Green",1,0)+IF(Input!V9="Green",1,0)+IF(Input!W9="Green",1,0)+IF(Input!X9="Green",1,0)+IF(Input!Y9="Green",1,0))*Input!R9 -> 0 | K3: =(IF(Input!L9="Red",1,0)+IF(Input!M9="Red",1,0)+IF(Input!N9="Red",1,0)+IF(Input!O9="Red",1,0)+IF(Input!P9="Red",1,0))*Input!I9+(IF(Input!U9="Red",1,0)+IF(Input!V9="Red",1,0)+IF(Input!W9="Red",1,0)+IF(Input!X9="Red",1,0)+IF(Input!Y9="Red",1,0))*Input!R9 -> 0 | L3: =(IF(Input!L9="Blue",1,0)+IF(Input!M9="Blue",1,0)+IF(Input!N9="Blue",1,0)+IF(Input!O9="Blue",1,0)+IF(Input!P9="Blue",1,0))*Input!I9+(IF(Input!U9="Blue",1,0)+IF(Input!V9="Blue",1,0)+IF(Input!W9="Blue",1,0)+IF(Input!X9="Blue",1,0)+IF(Input!Y9="Blue",1,0))*Input!R9 -> 0 | M3: =(IF(Input!L9="White",1,0)+IF(Input!M9="White",1,0)+IF(Input!N9="White",1,0)+IF(Input!O9="White",1,0)+IF(Input!P9="White",1,0))*Input!I9+(IF(Input!U9="White",1,0)+IF(Input!V9="White",1,0)+IF(Input!W9="White",1,0)+IF(Input!X9="White",1,0)+IF(Input!Y9="White",1,0))*Input!R9 -> 0 | N3: =(IF(Input!L9="Black",1,0)+IF(Input!M9="Black",1,0)+IF(Input!N9="Black",1,0)+IF(Input!O9="Black",1,0)+IF(Input!P9="Black",1,0))*Input!I9+(IF(Input!U9="Black",1,0)+IF(Input!V9="Black",1,0)+IF(Input!W9="Black",1,0)+IF(Input!X9="Black",1,0)+IF(Input!Y9="Black",1,0))*Input!R9 -> 0 | O3: =(IF(Input!L9="Colorless",1,0)+IF(Input!M9="Colorless",1,0)+IF(Input!N9="Colorless",1,0)+IF(Input!O9="Colorless",1,0)+IF(Input!P9="Colorless",1,0))*Input!I9+(IF(Input!U9="Colorless",1,0)+IF(Input!V9="Colorless",1,0)+IF(Input!W9="Colorless",1,0)+IF(Input!X9="Colorless",1,0)+IF(Input!Y9="Colorless",1,0))*Input!R9 -> 0 | Q3: =(IF(Input!Q9="Sorcery",1,0))*Input!I9+(IF(Input!Z9="Sorcery",1,0))*Input!R9 -> 0 | R3: =(IF(Input!Q9="Instant",1,0))*Input!I9+(IF(Input!Z9="Instant",1,0))*Input!R9 -> 0 | S3: =(IF(Input!Q9="Artifact",1,0))*Input!I9+(IF(Input!Z9="Artifact",1,0))*Input!R9 -> 0 | T3: =(IF(Input!Q9="Enchantment",1,0))*Input!I9+(IF(Input!Z9="Enchantment",1,0))*Input!R9 -> 0 | U3: =(IF(Input!Q9="Creature",1,0))*Input!I9+(IF(Input!Z9="Creature",1,0))*Input!R9 -> 0 | V3: =(IF(Input!Q9="Planeswalker",1,0))*Input!I9+(IF(Input!Z9="Planeswalker",1,0))*Input!R9 -> 0 | W3: Turn | X3: 1 | Y3: =B54/Input!$B$3*7 -> #DIV/0! | Z3: =C54/Input!$B$3*7 -> #DIV/0! | AA3: =D54/Input!$B$3*7 -> #DIV/0! | AB3: =E54/Input!$B$3*7 -> #DIV/0! | AC3: =F54/Input!$B$3*7 -> #DIV/0! | AD3: =G54/Input!$B$3*7 -> #DIV/0! | AF3: =IF(Input!K9=0,1,0)*Input!I9+IF(Input!T9=0,1,0)*Input!R9 -> 0 | AG3: =IF(Input!K9=1,1,0)*Input!I9+IF(Input!T9=1,1,0)*Input!R9 -> 0 | AH3: =IF(Input!K9=2,1,0)*Input!I9+IF(Input!T9=2,1,0)*Input!R9 -> 0 | AI3: =IF(Input!K9=3,1,0)*Input!I10+IF(Input!T9=3,1,0)*Input!R9 -> 0 | AJ3: =IF(Input!K9=4,1,0)*Input!I9+IF(Input!T9=4,1,0)*Input!R9 -> 0 | AK3: =IF(Input!K9=5,1,0)*Input!I9+IF(Input!T9=5,1,0)*Input!R9 -> 0 | AL3: =IF(Input!K9=6,1,0)*Input!I9+IF(Input!T9=6,1,0)*Input!R9 -> 0 | AM3: =IF(Input!K9=7,1,0)*Input!I9+IF(Input!T9=7,1,0)*Input!R9 -> 0 | AN3: =IF(Input!K9=8,1,0)*Input!I9+IF(Input!T9=8,1,0)*Input!R9 -> 0 | AO3: =IF(Input!K9=9,1,0)*Input!I9+IF(Input!T9=9,1,0)*Input!R9 -> 0 | AP3: =IF(Input!K9=10,1,0)*Input!I9+IF(Input!T9=10,1,0)*Input!R9 -> 0 | AQ3: =IF(Input!K9=11,1,0)*Input!I9+IF(Input!T9=11,1,0)*Input!R9 -> 0 | AR3: =IF(Input!K9=12,1,0)*Input!I9+IF(Input!T9=12,1,0)*Input!R9 -> 0 | AS3: =IF(Input!K9=13,1,0)*Input!I9+IF(Input!T9=13,1,0)*Input!R9 -> 0 | AT3: =IF(Input!K9=14,1,0)*Input!I9+IF(Input!T9=14,1,0)*Input!R9 -> 0 | AU3: =IF(Input!K9=15,1,0)*Input!I9+IF(Input!T9=15,1,0)*Input!R9 -> 0 | AV3: =IF(Input!K9=16,1,0)*Input!I9+IF(Input!T9=16,1,0)*Input!R9 -> 0
B4: =(IF(Input!C10="Green",1,0)+IF(Input!D10="Green",1,0)+IF(Input!E10="Green",1,0)+IF(Input!F10="Green",1,0)+IF(Input!G10="Green",1,0)+IF(Input!H10="Green",1,0))*Input!A10 -> 0 | C4: =(IF(Input!C10="Red",1,0)+IF(Input!D10="Red",1,0)+IF(Input!E10="Red",1,0)+IF(Input!F10="Red",1,0)+IF(Input!G10="Red",1,0)+IF(Input!H10="Red",1,0))*Input!A10 -> 0 | D4: =(IF(Input!C10="Blue",1,0)+IF(Input!D10="Blue",1,0)+IF(Input!E10="Blue",1,0)+IF(Input!F10="Blue",1,0)+IF(Input!G10="Blue",1,0)+IF(Input!H10="Blue",1,0))*Input!A10 -> 0 | E4: =(IF(Input!C10="White",1,0)+IF(Input!D10="White",1,0)+IF(Input!E10="White",1,0)+IF(Input!F10="White",1,0)+IF(Input!G10="White",1,0)+IF(Input!H10="White",1,0))*Input!A10 -> 0 | F4: =(IF(Input!C10="Black",1,0)+IF(Input!D10="Black",1,0)+IF(Input!E10="Black",1,0)+IF(Input!F10="Black",1,0)+IF(Input!G10="Black",1,0)+IF(Input!H10="Black",1,0))*Input!A10 -> 0 | G4: =(IF(Input!C10="Colorless",1,0)+IF(Input!D10="Colorless",1,0)+IF(Input!E10="Colorless",1,0)+IF(Input!F10="Colorless",1,0)+IF(Input!G10="Colorless",1,0)+IF(Input!H10="Colorless",1,0))*Input!A10 -> 0 | J4: =(IF(Input!L10="Green",1,0)+IF(Input!M10="Green",1,0)+IF(Input!N10="Green",1,0)+IF(Input!O10="Green",1,0)+IF(Input!P10="Green",1,0))*Input!I10+(IF(Input!U10="Green",1,0)+IF(Input!V10="Green",1,0)+IF(Input!W10="Green",1,0)+IF(Input!X10="Green",1,0)+IF(Input!Y10="Green",1,0))*Input!R10 -> 0 | K4: =(IF(Input!L10="Red",1,0)+IF(Input!M10="Red",1,0)+IF(Input!N10="Red",1,0)+IF(Input!O10="Red",1,0)+IF(Input!P10="Red",1,0))*Input!I10+(IF(Input!U10="Red",1,0)+IF(Input!V10="Red",1,0)+IF(Input!W10="Red",1,0)+IF(Input!X10="Red",1,0)+IF(Input!Y10="Red",1,0))*Input!R10 -> 0 | L4: =(IF(Input!L10="Blue",1,0)+IF(Input!M10="Blue",1,0)+IF(Input!N10="Blue",1,0)+IF(Input!O10="Blue",1,0)+IF(Input!P10="Blue",1,0))*Input!I10+(IF(Input!U10="Blue",1,0)+IF(Input!V10="Blue",1,0)+IF(Input!W10="Blue",1,0)+IF(Input!X10="Blue",1,0)+IF(Input!Y10="Blue",1,0))*Input!R10 -> 0 | M4: =(IF(Input!L10="White",1,0)+IF(Input!M10="White",1,0)+IF(Input!N10="White",1,0)+IF(Input!O10="White",1,0)+IF(Input!P10="White",1,0))*Input!I10+(IF(Input!U10="White",1,0)+IF(Input!V10="White",1,0)+IF(Input!W10="White",1,0)+IF(Input!X10="White",1,0)+IF(Input!Y10="White",1,0))*Input!R10 -> 0 | N4: =(IF(Input!L10="Black",1,0)+IF(Input!M10="Black",1,0)+IF(Input!N10="Black",1,0)+IF(Input!O10="Black",1,0)+IF(Input!P10="Black",1,0))*Input!I10+(IF(Input!U10="Black",1,0)+IF(Input!V10="Black",1,0)+IF(Input!W10="Black",1,0)+IF(Input!X10="Black",1,0)+IF(Input!Y10="Black",1,0))*Input!R10 -> 0 | O4: =(IF(Input!L10="Colorless",1,0)+IF(Input!M10="Colorless",1,0)+IF(Input!N10="Colorless",1,0)+IF(Input!O10="Colorless",1,0)+IF(Input!P10="Colorless",1,0))*Input!I10+(IF(Input!U10="Colorless",1,0)+IF(Input!V10="Colorless",1,0)+IF(Input!W10="Colorless",1,0)+IF(Input!X10="Colorless",1,0)+IF(Input!Y10="Colorless",1,0))*Input!R10 -> 0 | Q4: =(IF(Input!Q10="Sorcery",1,0))*Input!I10+(IF(Input!Z10="Sorcery",1,0))*Input!R10 -> 0 | R4: =(IF(Input!Q10="Instant",1,0))*Input!I10+(IF(Input!Z10="Instant",1,0))*Input!R10 -> 0 | S4: =(IF(Input!Q10="Artifact",1,0))*Input!I10+(IF(Input!Z10="Artifact",1,0))*Input!R10 -> 0 | T4: =(IF(Input!Q10="Enchantment",1,0))*Input!I10+(IF(Input!Z10="Enchantment",1,0))*Input!R10 -> 0 | U4: =(IF(Input!Q10="Creature",1,0))*Input!I10+(IF(Input!Z10="Creature",1,0))*Input!R10 -> 0 | V4: =(IF(Input!Q10="Planeswalker",1,0))*Input!I10+(IF(Input!Z10="Planeswalker",1,0))*Input!R10 -> 0 | X4: 2 | Y4: =B54/Input!$B$3*8 -> #DIV/0! | Z4: =C54/Input!$B$3*8 -> #DIV/0! | AA4: =D54/Input!$B$3*8 -> #DIV/0! | AB4: =E54/Input!$B$3*8 -> #DIV/0! | AC4: =F54/Input!$B$3*8 -> #DIV/0! | AD4: =G54/Input!$B$3*8 -> #DIV/0! | AF4: =IF(Input!K10=0,1,0)*Input!I10+IF(Input!T10=0,1,0)*Input!R10 -> 0 | AG4: =IF(Input!K10=1,1,0)*Input!I10+IF(Input!T10=1,1,0)*Input!R10 -> 0 | AH4: =IF(Input!K10=2,1,0)*Input!I10+IF(Input!T10=2,1,0)*Input!R10 -> 0 | AI4: =IF(Input!K10=3,1,0)*Input!I11+IF(Input!T10=3,1,0)*Input!R10 -> 0 | AJ4: =IF(Input!K10=4,1,0)*Input!I10+IF(Input!T10=4,1,0)*Input!R10 -> 0 | AK4: =IF(Input!K10=5,1,0)*Input!I10+IF(Input!T10=5,1,0)*Input!R10 -> 0 | AL4: =IF(Input!K10=6,1,0)*Input!I10+IF(Input!T10=6,1,0)*Input!R10 -> 0 | AM4: =IF(Input!K10=7,1,0)*Input!I10+IF(Input!T10=7,1,0)*Input!R10 -> 0 | AN4: =IF(Input!K10=8,1,0)*Input!I10+IF(Input!T10=8,1,0)*Input!R10 -> 0 | AO4: =IF(Input!K10=9,1,0)*Input!I10+IF(Input!T10=9,1,0)*Input!R10 -> 0 | AP4: =IF(Input!K10=10,1,0)*Input!I10+IF(Input!T10=10,1,0)*Input!R10 -> 0 | AQ4: =IF(Input!K10=11,1,0)*Input!I10+IF(Input!T10=11,1,0)*Input!R10 -> 0 | AR4: =IF(Input!K10=12,1,0)*Input!I10+IF(Input!T10=12,1,0)*Input!R10 -> 0 | AS4: =IF(Input!K10=13,1,0)*Input!I10+IF(Input!T10=13,1,0)*Input!R10 -> 0 | AT4: =IF(Input!K10=14,1,0)*Input!I10+IF(Input!T10=14,1,0)*Input!R10 -> 0 | AU4: =IF(Input!K10=15,1,0)*Input!I10+IF(Input!T10=15,1,0)*Input!R10 -> 0 | AV4: =IF(Input!K10=16,1,0)*Input!I10+IF(Input!T10=16,1,0)*Input!R10 -> 0
B5: =(IF(Input!C11="Green",1,0)+IF(Input!D11="Green",1,0)+IF(Input!E11="Green",1,0)+IF(Input!F11="Green",1,0)+IF(Input!G11="Green",1,0)+IF(Input!H11="Green",1,0))*Input!A11 -> 0 | C5: =(IF(Input!C11="Red",1,0)+IF(Input!D11="Red",1,0)+IF(Input!E11="Red",1,0)+IF(Input!F11="Red",1,0)+IF(Input!G11="Red",1,0)+IF(Input!H11="Red",1,0))*Input!A11 -> 0 | D5: =(IF(Input!C11="Blue",1,0)+IF(Input!D11="Blue",1,0)+IF(Input!E11="Blue",1,0)+IF(Input!F11="Blue",1,0)+IF(Input!G11="Blue",1,0)+IF(Input!H11="Blue",1,0))*Input!A11 -> 0 | E5: =(IF(Input!C11="White",1,0)+IF(Input!D11="White",1,0)+IF(Input!E11="White",1,0)+IF(Input!F11="White",1,0)+IF(Input!G11="White",1,0)+IF(Input!H11="White",1,0))*Input!A11 -> 0 | F5: =(IF(Input!C11="Black",1,0)+IF(Input!D11="Black",1,0)+IF(Input!E11="Black",1,0)+IF(Input!F11="Black",1,0)+IF(Input!G11="Black",1,0)+IF(Input!H11="Black",1,0))*Input!A11 -> 0 | G5: =(IF(Input!C11="Colorless",1,0)+IF(Input!D11="Colorless",1,0)+IF(Input!E11="Colorless",1,0)+IF(Input!F11="Colorless",1,0)+IF(Input!G11="Colorless",1,0)+IF(Input!H11="Colorless",1,0))*Input!A11 -> 0 | J5: =(IF(Input!L11="Green",1,0)+IF(Input!M11="Green",1,0)+IF(Input!N11="Green",1,0)+IF(Input!O11="Green",1,0)+IF(Input!P11="Green",1,0))*Input!I11+(IF(Input!U11="Green",1,0)+IF(Input!V11="Green",1,0)+IF(Input!W11="Green",1,0)+IF(Input!X11="Green",1,0)+IF(Input!Y11="Green",1,0))*Input!R11 -> 0 | K5: =(IF(Input!L11="Red",1,0)+IF(Input!M11="Red",1,0)+IF(Input!N11="Red",1,0)+IF(Input!O11="Red",1,0)+IF(Input!P11="Red",1,0))*Input!I11+(IF(Input!U11="Red",1,0)+IF(Input!V11="Red",1,0)+IF(Input!W11="Red",1,0)+IF(Input!X11="Red",1,0)+IF(Input!Y11="Red",1,0))*Input!R11 -> 0 | L5: =(IF(Input!L11="Blue",1,0)+IF(Input!M11="Blue",1,0)+IF(Input!N11="Blue",1,0)+IF(Input!O11="Blue",1,0)+IF(Input!P11="Blue",1,0))*Input!I11+(IF(Input!U11="Blue",1,0)+IF(Input!V11="Blue",1,0)+IF(Input!W11="Blue",1,0)+IF(Input!X11="Blue",1,0)+IF(Input!Y11="Blue",1,0))*Input!R11 -> 0 | M5: =(IF(Input!L11="White",1,0)+IF(Input!M11="White",1,0)+IF(Input!N11="White",1,0)+IF(Input!O11="White",1,0)+IF(Input!P11="White",1,0))*Input!I11+(IF(Input!U11="White",1,0)+IF(Input!V11="White",1,0)+IF(Input!W11="White",1,0)+IF(Input!X11="White",1,0)+IF(Input!Y11="White",1,0))*Input!R11 -> 0 | N5: =(IF(Input!L11="Black",1,0)+IF(Input!M11="Black",1,0)+IF(Input!N11="Black",1,0)+IF(Input!O11="Black",1,0)+IF(Input!P11="Black",1,0))*Input!I11+(IF(Input!U11="Black",1,0)+IF(Input!V11="Black",1,0)+IF(Input!W11="Black",1,0)+IF(Input!X11="Black",1,0)+IF(Input!Y11="Black",1,0))*Input!R11 -> 0 | O5: =(IF(Input!L11="Colorless",1,0)+IF(Input!M11="Colorless",1,0)+IF(Input!N11="Colorless",1,0)+IF(Input!O11="Colorless",1,0)+IF(Input!P11="Colorless",1,0))*Input!I11+(IF(Input!U11="Colorless",1,0)+IF(Input!V11="Colorless",1,0)+IF(Input!W11="Colorless",1,0)+IF(Input!X11="Colorless",1,0)+IF(Input!Y11="Colorless",1,0))*Input!R11 -> 0 | Q5: =(IF(Input!Q11="Sorcery",1,0))*Input!I11+(IF(Input!Z11="Sorcery",1,0))*Input!R11 -> 0 | R5: =(IF(Input!Q11="Instant",1,0))*Input!I11+(IF(Input!Z11="Instant",1,0))*Input!R11 -> 0 | S5: =(IF(Input!Q11="Artifact",1,0))*Input!I11+(IF(Input!Z11="Artifact",1,0))*Input!R11 -> 0 | T5: =(IF(Input!Q11="Enchantment",1,0))*Input!I11+(IF(Input!Z11="Enchantment",1,0))*Input!R11 -> 0 | U5: =(IF(Input!Q11="Creature",1,0))*Input!I11+(IF(Input!Z11="Creature",1,0))*Input!R11 -> 0 | V5: =(IF(Input!Q11="Planeswalker",1,0))*Input!I11+(IF(Input!Z11="Planeswalker",1,0))*Input!R11 -> 0 | X5: 3 | Y5: =B54/Input!$B$3*9 -> #DIV/0! | Z5: =C54/Input!$B$3*9 -> #DIV/0! | AA5: =D54/Input!$B$3*9 -> #DIV/0! | AB5: =E54/Input!$B$3*9 -> #DIV/0! | AC5: =F54/Input!$B$3*9 -> #DIV/0! | AD5: =G54/Input!$B$3*9 -> #DIV/0! | AF5: =IF(Input!K11=0,1,0)*Input!I11+IF(Input!T11=0,1,0)*Input!R11 -> 0 | AG5: =IF(Input!K11=1,1,0)*Input!I11+IF(Input!T11=1,1,0)*Input!R11 -> 0 | AH5: =IF(Input!K11=2,1,0)*Input!I11+IF(Input!T11=2,1,0)*Input!R11 -> 0 | AI5: =IF(Input!K11=3,1,0)*Input!I12+IF(Input!T11=3,1,0)*Input!R11 -> 0 | AJ5: =IF(Input!K11=4,1,0)*Input!I11+IF(Input!T11=4,1,0)*Input!R11 -> 0 | AK5: =IF(Input!K11=5,1,0)*Input!I11+IF(Input!T11=5,1,0)*Input!R11 -> 0 | AL5: =IF(Input!K11=6,1,0)*Input!I11+IF(Input!T11=6,1,0)*Input!R11 -> 0 | AM5: =IF(Input!K11=7,1,0)*Input!I11+IF(Input!T11=7,1,0)*Input!R11 -> 0 | AN5: =IF(Input!K11=8,1,0)*Input!I11+IF(Input!T11=8,1,0)*Input!R11 -> 0 | AO5: =IF(Input!K11=9,1,0)*Input!I11+IF(Input!T11=9,1,0)*Input!R11 -> 0 | AP5: =IF(Input!K11=10,1,0)*Input!I11+IF(Input!T11=10,1,0)*Input!R11 -> 0 | AQ5: =IF(Input!K11=11,1,0)*Input!I11+IF(Input!T11=11,1,0)*Input!R11 -> 0 | AR5: =IF(Input!K11=12,1,0)*Input!I11+IF(Input!T11=12,1,0)*Input!R11 -> 0 | AS5: =IF(Input!K11=13,1,0)*Input!I11+IF(Input!T11=13,1,0)*Input!R11 -> 0 | AT5: =IF(Input!K11=14,1,0)*Input!I11+IF(Input!T11=14,1,0)*Input!R11 -> 0 | AU5: =IF(Input!K11=15,1,0)*Input!I11+IF(Input!T11=15,1,0)*Input!R11 -> 0 | AV5: =IF(Input!K11=16,1,0)*Input!I11+IF(Input!T11=16,1,0)*Input!R11 -> 0
B6: =(IF(Input!C12="Green",1,0)+IF(Input!D12="Green",1,0)+IF(Input!E12="Green",1,0)+IF(Input!F12="Green",1,0)+IF(Input!G12="Green",1,0)+IF(Input!H12="Green",1,0))*Input!A12 -> 0 | C6: =(IF(Input!C12="Red",1,0)+IF(Input!D12="Red",1,0)+IF(Input!E12="Red",1,0)+IF(Input!F12="Red",1,0)+IF(Input!G12="Red",1,0)+IF(Input!H12="Red",1,0))*Input!A12 -> 0 | D6: =(IF(Input!C12="Blue",1,0)+IF(Input!D12="Blue",1,0)+IF(Input!E12="Blue",1,0)+IF(Input!F12="Blue",1,0)+IF(Input!G12="Blue",1,0)+IF(Input!H12="Blue",1,0))*Input!A12 -> 0 | E6: =(IF(Input!C12="White",1,0)+IF(Input!D12="White",1,0)+IF(Input!E12="White",1,0)+IF(Input!F12="White",1,0)+IF(Input!G12="White",1,0)+IF(Input!H12="White",1,0))*Input!A12 -> 0 | F6: =(IF(Input!C12="Black",1,0)+IF(Input!D12="Black",1,0)+IF(Input!E12="Black",1,0)+IF(Input!F12="Black",1,0)+IF(Input!G12="Black",1,0)+IF(Input!H12="Black",1,0))*Input!A12 -> 0 | G6: =(IF(Input!C12="Colorless",1,0)+IF(Input!D12="Colorless",1,0)+IF(Input!E12="Colorless",1,0)+IF(Input!F12="Colorless",1,0)+IF(Input!G12="Colorless",1,0)+IF(Input!H12="Colorless",1,0))*Input!A12 -> 0 | J6: =(IF(Input!L12="Green",1,0)+IF(Input!M12="Green",1,0)+IF(Input!N12="Green",1,0)+IF(Input!O12="Green",1,0)+IF(Input!P12="Green",1,0))*Input!I12+(IF(Input!U12="Green",1,0)+IF(Input!V12="Green",1,0)+IF(Input!W12="Green",1,0)+IF(Input!X12="Green",1,0)+IF(Input!Y12="Green",1,0))*Input!R12 -> 0 | K6: =(IF(Input!L12="Red",1,0)+IF(Input!M12="Red",1,0)+IF(Input!N12="Red",1,0)+IF(Input!O12="Red",1,0)+IF(Input!P12="Red",1,0))*Input!I12+(IF(Input!U12="Red",1,0)+IF(Input!V12="Red",1,0)+IF(Input!W12="Red",1,0)+IF(Input!X12="Red",1,0)+IF(Input!Y12="Red",1,0))*Input!R12 -> 0 | L6: =(IF(Input!L12="Blue",1,0)+IF(Input!M12="Blue",1,0)+IF(Input!N12="Blue",1,0)+IF(Input!O12="Blue",1,0)+IF(Input!P12="Blue",1,0))*Input!I12+(IF(Input!U12="Blue",1,0)+IF(Input!V12="Blue",1,0)+IF(Input!W12="Blue",1,0)+IF(Input!X12="Blue",1,0)+IF(Input!Y12="Blue",1,0))*Input!R12 -> 0 | M6: =(IF(Input!L12="White",1,0)+IF(Input!M12="White",1,0)+IF(Input!N12="White",1,0)+IF(Input!O12="White",1,0)+IF(Input!P12="White",1,0))*Input!I12+(IF(Input!U12="White",1,0)+IF(Input!V12="White",1,0)+IF(Input!W12="White",1,0)+IF(Input!X12="White",1,0)+IF(Input!Y12="White",1,0))*Input!R12 -> 0 | N6: =(IF(Input!L12="Black",1,0)+IF(Input!M12="Black",1,0)+IF(Input!N12="Black",1,0)+IF(Input!O12="Black",1,0)+IF(Input!P12="Black",1,0))*Input!I12+(IF(Input!U12="Black",1,0)+IF(Input!V12="Black",1,0)+IF(Input!W12="Black",1,0)+IF(Input!X12="Black",1,0)+IF(Input!Y12="Black",1,0))*Input!R12 -> 0 | O6: =(IF(Input!L12="Colorless",1,0)+IF(Input!M12="Colorless",1,0)+IF(Input!N12="Colorless",1,0)+IF(Input!O12="Colorless",1,0)+IF(Input!P12="Colorless",1,0))*Input!I12+(IF(Input!U12="Colorless",1,0)+IF(Input!V12="Colorless",1,0)+IF(Input!W12="Colorless",1,0)+IF(Input!X12="Colorless",1,0)+IF(Input!Y12="Colorless",1,0))*Input!R12 -> 0 | Q6: =(IF(Input!Q12="Sorcery",1,0))*Input!I12+(IF(Input!Z12="Sorcery",1,0))*Input!R12 -> 0 | R6: =(IF(Input!Q12="Instant",1,0))*Input!I12+(IF(Input!Z12="Instant",1,0))*Input!R12 -> 0 | S6: =(IF(Input!Q12="Artifact",1,0))*Input!I12+(IF(Input!Z12="Artifact",1,0))*Input!R12 -> 0 | T6: =(IF(Input!Q12="Enchantment",1,0))*Input!I12+(IF(Input!Z12="Enchantment",1,0))*Input!R12 -> 0 | U6: =(IF(Input!Q12="Creature",1,0))*Input!I12+(IF(Input!Z12="Creature",1,0))*Input!R12 -> 0 | V6: =(IF(Input!Q12="Planeswalker",1,0))*Input!I12+(IF(Input!Z12="Planeswalker",1,0))*Input!R12 -> 0 | X6: 4 | Y6: =B54/Input!$B$3*10 -> #DIV/0! | Z6: =C54/Input!$B$3*10 -> #DIV/0! | AA6: =D54/Input!$B$3*10 -> #DIV/0! | AB6: =E54/Input!$B$3*10 -> #DIV/0! | AC6: =F54/Input!$B$3*10 -> #DIV/0! | AD6: =G54/Input!$B$3*10 -> #DIV/0! | AF6: =IF(Input!K12=0,1,0)*Input!I12+IF(Input!T12=0,1,0)*Input!R12 -> 0 | AG6: =IF(Input!K12=1,1,0)*Input!I12+IF(Input!T12=1,1,0)*Input!R12 -> 0 | AH6: =IF(Input!K12=2,1,0)*Input!I12+IF(Input!T12=2,1,0)*Input!R12 -> 0 | AI6: =IF(Input!K12=3,1,0)*Input!I13+IF(Input!T12=3,1,0)*Input!R12 -> 0 | AJ6: =IF(Input!K12=4,1,0)*Input!I12+IF(Input!T12=4,1,0)*Input!R12 -> 0 | AK6: =IF(Input!K12=5,1,0)*Input!I12+IF(Input!T12=5,1,0)*Input!R12 -> 0 | AL6: =IF(Input!K12=6,1,0)*Input!I12+IF(Input!T12=6,1,0)*Input!R12 -> 0 | AM6: =IF(Input!K12=7,1,0)*Input!I12+IF(Input!T12=7,1,0)*Input!R12 -> 0 | AN6: =IF(Input!K12=8,1,0)*Input!I12+IF(Input!T12=8,1,0)*Input!R12 -> 0 | AO6: =IF(Input!K12=9,1,0)*Input!I12+IF(Input!T12=9,1,0)*Input!R12 -> 0 | AP6: =IF(Input!K12=10,1,0)*Input!I12+IF(Input!T12=10,1,0)*Input!R12 -> 0 | AQ6: =IF(Input!K12=11,1,0)*Input!I12+IF(Input!T12=11,1,0)*Input!R12 -> 0 | AR6: =IF(Input!K12=12,1,0)*Input!I12+IF(Input!T12=12,1,0)*Input!R12 -> 0 | AS6: =IF(Input!K12=13,1,0)*Input!I12+IF(Input!T12=13,1,0)*Input!R12 -> 0 | AT6: =IF(Input!K12=14,1,0)*Input!I12+IF(Input!T12=14,1,0)*Input!R12 -> 0 | AU6: =IF(Input!K12=15,1,0)*Input!I12+IF(Input!T12=15,1,0)*Input!R12 -> 0 | AV6: =IF(Input!K12=16,1,0)*Input!I12+IF(Input!T12=16,1,0)*Input!R12 -> 0
B7: =(IF(Input!C13="Green",1,0)+IF(Input!D13="Green",1,0)+IF(Input!E13="Green",1,0)+IF(Input!F13="Green",1,0)+IF(Input!G13="Green",1,0)+IF(Input!H13="Green",1,0))*Input!A13 -> 0 | C7: =(IF(Input!C13="Red",1,0)+IF(Input!D13="Red",1,0)+IF(Input!E13="Red",1,0)+IF(Input!F13="Red",1,0)+IF(Input!G13="Red",1,0)+IF(Input!H13="Red",1,0))*Input!A13 -> 0 | D7: =(IF(Input!C13="Blue",1,0)+IF(Input!D13="Blue",1,0)+IF(Input!E13="Blue",1,0)+IF(Input!F13="Blue",1,0)+IF(Input!G13="Blue",1,0)+IF(Input!H13="Blue",1,0))*Input!A13 -> 0 | E7: =(IF(Input!C13="White",1,0)+IF(Input!D13="White",1,0)+IF(Input!E13="White",1,0)+IF(Input!F13="White",1,0)+IF(Input!G13="White",1,0)+IF(Input!H13="White",1,0))*Input!A13 -> 0 | F7: =(IF(Input!C13="Black",1,0)+IF(Input!D13="Black",1,0)+IF(Input!E13="Black",1,0)+IF(Input!F13="Black",1,0)+IF(Input!G13="Black",1,0)+IF(Input!H13="Black",1,0))*Input!A13 -> 0 | G7: =(IF(Input!C13="Colorless",1,0)+IF(Input!D13="Colorless",1,0)+IF(Input!E13="Colorless",1,0)+IF(Input!F13="Colorless",1,0)+IF(Input!G13="Colorless",1,0)+IF(Input!H13="Colorless",1,0))*Input!A13 -> 0 | J7: =(IF(Input!L13="Green",1,0)+IF(Input!M13="Green",1,0)+IF(Input!N13="Green",1,0)+IF(Input!O13="Green",1,0)+IF(Input!P13="Green",1,0))*Input!I13+(IF(Input!U13="Green",1,0)+IF(Input!V13="Green",1,0)+IF(Input!W13="Green",1,0)+IF(Input!X13="Green",1,0)+IF(Input!Y13="Green",1,0))*Input!R13 -> 0 | K7: =(IF(Input!L13="Red",1,0)+IF(Input!M13="Red",1,0)+IF(Input!N13="Red",1,0)+IF(Input!O13="Red",1,0)+IF(Input!P13="Red",1,0))*Input!I13+(IF(Input!U13="Red",1,0)+IF(Input!V13="Red",1,0)+IF(Input!W13="Red",1,0)+IF(Input!X13="Red",1,0)+IF(Input!Y13="Red",1,0))*Input!R13 -> 0 | L7: =(IF(Input!L13="Blue",1,0)+IF(Input!M13="Blue",1,0)+IF(Input!N13="Blue",1,0)+IF(Input!O13="Blue",1,0)+IF(Input!P13="Blue",1,0))*Input!I13+(IF(Input!U13="Blue",1,0)+IF(Input!V13="Blue",1,0)+IF(Input!W13="Blue",1,0)+IF(Input!X13="Blue",1,0)+IF(Input!Y13="Blue",1,0))*Input!R13 -> 0 | M7: =(IF(Input!L13="White",1,0)+IF(Input!M13="White",1,0)+IF(Input!N13="White",1,0)+IF(Input!O13="White",1,0)+IF(Input!P13="White",1,0))*Input!I13+(IF(Input!U13="White",1,0)+IF(Input!V13="White",1,0)+IF(Input!W13="White",1,0)+IF(Input!X13="White",1,0)+IF(Input!Y13="White",1,0))*Input!R13 -> 0 | N7: =(IF(Input!L13="Black",1,0)+IF(Input!M13="Black",1,0)+IF(Input!N13="Black",1,0)+IF(Input!O13="Black",1,0)+IF(Input!P13="Black",1,0))*Input!I13+(IF(Input!U13="Black",1,0)+IF(Input!V13="Black",1,0)+IF(Input!W13="Black",1,0)+IF(Input!X13="Black",1,0)+IF(Input!Y13="Black",1,0))*Input!R13 -> 0 | O7: =(IF(Input!L13="Colorless",1,0)+IF(Input!M13="Colorless",1,0)+IF(Input!N13="Colorless",1,0)+IF(Input!O13="Colorless",1,0)+IF(Input!P13="Colorless",1,0))*Input!I13+(IF(Input!U13="Colorless",1,0)+IF(Input!V13="Colorless",1,0)+IF(Input!W13="Colorless",1,0)+IF(Input!X13="Colorless",1,0)+IF(Input!Y13="Colorless",1,0))*Input!R13 -> 0 | Q7: =(IF(Input!Q13="Sorcery",1,0))*Input!I13+(IF(Input!Z13="Sorcery",1,0))*Input!R13 -> 0 | R7: =(IF(Input!Q13="Instant",1,0))*Input!I13+(IF(Input!Z13="Instant",1,0))*Input!R13 -> 0 | S7: =(IF(Input!Q13="Artifact",1,0))*Input!I13+(IF(Input!Z13="Artifact",1,0))*Input!R13 -> 0 | T7: =(IF(Input!Q13="Enchantment",1,0))*Input!I13+(IF(Input!Z13="Enchantment",1,0))*Input!R13 -> 0 | U7: =(IF(Input!Q13="Creature",1,0))*Input!I13+(IF(Input!Z13="Creature",1,0))*Input!R13 -> 0 | V7: =(IF(Input!Q13="Planeswalker",1,0))*Input!I13+(IF(Input!Z13="Planeswalker",1,0))*Input!R13 -> 0 | X7: 5 | Y7: =B54/Input!$B$3*11 -> #DIV/0! | Z7: =C54/Input!$B$3*11 -> #DIV/0! | AA7: =D54/Input!$B$3*11 -> #DIV/0! | AB7: =E54/Input!$B$3*11 -> #DIV/0! | AC7: =F54/Input!$B$3*11 -> #DIV/0! | AD7: =G54/Input!$B$3*11 -> #DIV/0! | AF7: =IF(Input!K13=0,1,0)*Input!I13+IF(Input!T13=0,1,0)*Input!R13 -> 0 | AG7: =IF(Input!K13=1,1,0)*Input!I13+IF(Input!T13=1,1,0)*Input!R13 -> 0 | AH7: =IF(Input!K13=2,1,0)*Input!I13+IF(Input!T13=2,1,0)*Input!R13 -> 0 | AI7: =IF(Input!K13=3,1,0)*Input!I14+IF(Input!T13=3,1,0)*Input!R13 -> 0 | AJ7: =IF(Input!K13=4,1,0)*Input!I13+IF(Input!T13=4,1,0)*Input!R13 -> 0 | AK7: =IF(Input!K13=5,1,0)*Input!I13+IF(Input!T13=5,1,0)*Input!R13 -> 0 | AL7: =IF(Input!K13=6,1,0)*Input!I13+IF(Input!T13=6,1,0)*Input!R13 -> 0 | AM7: =IF(Input!K13=7,1,0)*Input!I13+IF(Input!T13=7,1,0)*Input!R13 -> 0 | AN7: =IF(Input!K13=8,1,0)*Input!I13+IF(Input!T13=8,1,0)*Input!R13 -> 0 | AO7: =IF(Input!K13=9,1,0)*Input!I13+IF(Input!T13=9,1,0)*Input!R13 -> 0 | AP7: =IF(Input!K13=10,1,0)*Input!I13+IF(Input!T13=10,1,0)*Input!R13 -> 0 | AQ7: =IF(Input!K13=11,1,0)*Input!I13+IF(Input!T13=11,1,0)*Input!R13 -> 0 | AR7: =IF(Input!K13=12,1,0)*Input!I13+IF(Input!T13=12,1,0)*Input!R13 -> 0 | AS7: =IF(Input!K13=13,1,0)*Input!I13+IF(Input!T13=13,1,0)*Input!R13 -> 0 | AT7: =IF(Input!K13=14,1,0)*Input!I13+IF(Input!T13=14,1,0)*Input!R13 -> 0 | AU7: =IF(Input!K13=15,1,0)*Input!I13+IF(Input!T13=15,1,0)*Input!R13 -> 0 | AV7: =IF(Input!K13=16,1,0)*Input!I13+IF(Input!T13=16,1,0)*Input!R13 -> 0
B8: =(IF(Input!C14="Green",1,0)+IF(Input!D14="Green",1,0)+IF(Input!E14="Green",1,0)+IF(Input!F14="Green",1,0)+IF(Input!G14="Green",1,0)+IF(Input!H14="Green",1,0))*Input!A14 -> 0 | C8: =(IF(Input!C14="Red",1,0)+IF(Input!D14="Red",1,0)+IF(Input!E14="Red",1,0)+IF(Input!F14="Red",1,0)+IF(Input!G14="Red",1,0)+IF(Input!H14="Red",1,0))*Input!A14 -> 0 | D8: =(IF(Input!C14="Blue",1,0)+IF(Input!D14="Blue",1,0)+IF(Input!E14="Blue",1,0)+IF(Input!F14="Blue",1,0)+IF(Input!G14="Blue",1,0)+IF(Input!H14="Blue",1,0))*Input!A14 -> 0 | E8: =(IF(Input!C14="White",1,0)+IF(Input!D14="White",1,0)+IF(Input!E14="White",1,0)+IF(Input!F14="White",1,0)+IF(Input!G14="White",1,0)+IF(Input!H14="White",1,0))*Input!A14 -> 0 | F8: =(IF(Input!C14="Black",1,0)+IF(Input!D14="Black",1,0)+IF(Input!E14="Black",1,0)+IF(Input!F14="Black",1,0)+IF(Input!G14="Black",1,0)+IF(Input!H14="Black",1,0))*Input!A14 -> 0 | G8: =(IF(Input!C14="Colorless",1,0)+IF(Input!D14="Colorless",1,0)+IF(Input!E14="Colorless",1,0)+IF(Input!F14="Colorless",1,0)+IF(Input!G14="Colorless",1,0)+IF(Input!H14="Colorless",1,0))*Input!A14 -> 0 | J8: =(IF(Input!L14="Green",1,0)+IF(Input!M14="Green",1,0)+IF(Input!N14="Green",1,0)+IF(Input!O14="Green",1,0)+IF(Input!P14="Green",1,0))*Input!I14+(IF(Input!U14="Green",1,0)+IF(Input!V14="Green",1,0)+IF(Input!W14="Green",1,0)+IF(Input!X14="Green",1,0)+IF(Input!Y14="Green",1,0))*Input!R14 -> 0 | K8: =(IF(Input!L14="Red",1,0)+IF(Input!M14="Red",1,0)+IF(Input!N14="Red",1,0)+IF(Input!O14="Red",1,0)+IF(Input!P14="Red",1,0))*Input!I14+(IF(Input!U14="Red",1,0)+IF(Input!V14="Red",1,0)+IF(Input!W14="Red",1,0)+IF(Input!X14="Red",1,0)+IF(Input!Y14="Red",1,0))*Input!R14 -> 0 | L8: =(IF(Input!L14="Blue",1,0)+IF(Input!M14="Blue",1,0)+IF(Input!N14="Blue",1,0)+IF(Input!O14="Blue",1,0)+IF(Input!P14="Blue",1,0))*Input!I14+(IF(Input!U14="Blue",1,0)+IF(Input!V14="Blue",1,0)+IF(Input!W14="Blue",1,0)+IF(Input!X14="Blue",1,0)+IF(Input!Y14="Blue",1,0))*Input!R14 -> 0 | M8: =(IF(Input!L14="White",1,0)+IF(Input!M14="White",1,0)+IF(Input!N14="White",1,0)+IF(Input!O14="White",1,0)+IF(Input!P14="White",1,0))*Input!I14+(IF(Input!U14="White",1,0)+IF(Input!V14="White",1,0)+IF(Input!W14="White",1,0)+IF(Input!X14="White",1,0)+IF(Input!Y14="White",1,0))*Input!R14 -> 0 | N8: =(IF(Input!L14="Black",1,0)+IF(Input!M14="Black",1,0)+IF(Input!N14="Black",1,0)+IF(Input!O14="Black",1,0)+IF(Input!P14="Black",1,0))*Input!I14+(IF(Input!U14="Black",1,0)+IF(Input!V14="Black",1,0)+IF(Input!W14="Black",1,0)+IF(Input!X14="Black",1,0)+IF(Input!Y14="Black",1,0))*Input!R14 -> 0 | O8: =(IF(Input!L14="Colorless",1,0)+IF(Input!M14="Colorless",1,0)+IF(Input!N14="Colorless",1,0)+IF(Input!O14="Colorless",1,0)+IF(Input!P14="Colorless",1,0))*Input!I14+(IF(Input!U14="Colorless",1,0)+IF(Input!V14="Colorless",1,0)+IF(Input!W14="Colorless",1,0)+IF(Input!X14="Colorless",1,0)+IF(Input!Y14="Colorless",1,0))*Input!R14 -> 0 | Q8: =(IF(Input!Q14="Sorcery",1,0))*Input!I14+(IF(Input!Z14="Sorcery",1,0))*Input!R14 -> 0 | R8: =(IF(Input!Q14="Instant",1,0))*Input!I14+(IF(Input!Z14="Instant",1,0))*Input!R14 -> 0 | S8: =(IF(Input!Q14="Artifact",1,0))*Input!I14+(IF(Input!Z14="Artifact",1,0))*Input!R14 -> 0 | T8: =(IF(Input!Q14="Enchantment",1,0))*Input!I14+(IF(Input!Z14="Enchantment",1,0))*Input!R14 -> 0 | U8: =(IF(Input!Q14="Creature",1,0))*Input!I14+(IF(Input!Z14="Creature",1,0))*Input!R14 -> 0 | V8: =(IF(Input!Q14="Planeswalker",1,0))*Input!I14+(IF(Input!Z14="Planeswalker",1,0))*Input!R14 -> 0 | AF8: =IF(Input!K14=0,1,0)*Input!I14+IF(Input!T14=0,1,0)*Input!R14 -> 0 | AG8: =IF(Input!K14=1,1,0)*Input!I14+IF(Input!T14=1,1,0)*Input!R14 -> 0 | AH8: =IF(Input!K14=2,1,0)*Input!I14+IF(Input!T14=2,1,0)*Input!R14 -> 0 | AI8: =IF(Input!K14=3,1,0)*Input!I15+IF(Input!T14=3,1,0)*Input!R14 -> 0 | AJ8: =IF(Input!K14=4,1,0)*Input!I14+IF(Input!T14=4,1,0)*Input!R14 -> 0 | AK8: =IF(Input!K14=5,1,0)*Input!I14+IF(Input!T14=5,1,0)*Input!R14 -> 0 | AL8: =IF(Input!K14=6,1,0)*Input!I14+IF(Input!T14=6,1,0)*Input!R14 -> 0 | AM8: =IF(Input!K14=7,1,0)*Input!I14+IF(Input!T14=7,1,0)*Input!R14 -> 0 | AN8: =IF(Input!K14=8,1,0)*Input!I14+IF(Input!T14=8,1,0)*Input!R14 -> 0 | AO8: =IF(Input!K14=9,1,0)*Input!I14+IF(Input!T14=9,1,0)*Input!R14 -> 0 | AP8: =IF(Input!K14=10,1,0)*Input!I14+IF(Input!T14=10,1,0)*Input!R14 -> 0 | AQ8: =IF(Input!K14=11,1,0)*Input!I14+IF(Input!T14=11,1,0)*Input!R14 -> 0 | AR8: =IF(Input!K14=12,1,0)*Input!I14+IF(Input!T14=12,1,0)*Input!R14 -> 0 | AS8: =IF(Input!K14=13,1,0)*Input!I14+IF(Input!T14=13,1,0)*Input!R14 -> 0 | AT8: =IF(Input!K14=14,1,0)*Input!I14+IF(Input!T14=14,1,0)*Input!R14 -> 0 | AU8: =IF(Input!K14=15,1,0)*Input!I14+IF(Input!T14=15,1,0)*Input!R14 -> 0 | AV8: =IF(Input!K14=16,1,0)*Input!I14+IF(Input!T14=16,1,0)*Input!R14 -> 0
B9: =(IF(Input!C15="Green",1,0)+IF(Input!D15="Green",1,0)+IF(Input!E15="Green",1,0)+IF(Input!F15="Green",1,0)+IF(Input!G15="Green",1,0)+IF(Input!H15="Green",1,0))*Input!A15 -> 0 | C9: =(IF(Input!C15="Red",1,0)+IF(Input!D15="Red",1,0)+IF(Input!E15="Red",1,0)+IF(Input!F15="Red",1,0)+IF(Input!G15="Red",1,0)+IF(Input!H15="Red",1,0))*Input!A15 -> 0 | D9: =(IF(Input!C15="Blue",1,0)+IF(Input!D15="Blue",1,0)+IF(Input!E15="Blue",1,0)+IF(Input!F15="Blue",1,0)+IF(Input!G15="Blue",1,0)+IF(Input!H15="Blue",1,0))*Input!A15 -> 0 | E9: =(IF(Input!C15="White",1,0)+IF(Input!D15="White",1,0)+IF(Input!E15="White",1,0)+IF(Input!F15="White",1,0)+IF(Input!G15="White",1,0)+IF(Input!H15="White",1,0))*Input!A15 -> 0 | F9: =(IF(Input!C15="Black",1,0)+IF(Input!D15="Black",1,0)+IF(Input!E15="Black",1,0)+IF(Input!F15="Black",1,0)+IF(Input!G15="Black",1,0)+IF(Input!H15="Black",1,0))*Input!A15 -> 0 | G9: =(IF(Input!C15="Colorless",1,0)+IF(Input!D15="Colorless",1,0)+IF(Input!E15="Colorless",1,0)+IF(Input!F15="Colorless",1,0)+IF(Input!G15="Colorless",1,0)+IF(Input!H15="Colorless",1,0))*Input!A15 -> 0 | J9: =(IF(Input!L15="Green",1,0)+IF(Input!M15="Green",1,0)+IF(Input!N15="Green",1,0)+IF(Input!O15="Green",1,0)+IF(Input!P15="Green",1,0))*Input!I15+(IF(Input!U15="Green",1,0)+IF(Input!V15="Green",1,0)+IF(Input!W15="Green",1,0)+IF(Input!X15="Green",1,0)+IF(Input!Y15="Green",1,0))*Input!R15 -> 0 | K9: =(IF(Input!L15="Red",1,0)+IF(Input!M15="Red",1,0)+IF(Input!N15="Red",1,0)+IF(Input!O15="Red",1,0)+IF(Input!P15="Red",1,0))*Input!I15+(IF(Input!U15="Red",1,0)+IF(Input!V15="Red",1,0)+IF(Input!W15="Red",1,0)+IF(Input!X15="Red",1,0)+IF(Input!Y15="Red",1,0))*Input!R15 -> 0 | L9: =(IF(Input!L15="Blue",1,0)+IF(Input!M15="Blue",1,0)+IF(Input!N15="Blue",1,0)+IF(Input!O15="Blue",1,0)+IF(Input!P15="Blue",1,0))*Input!I15+(IF(Input!U15="Blue",1,0)+IF(Input!V15="Blue",1,0)+IF(Input!W15="Blue",1,0)+IF(Input!X15="Blue",1,0)+IF(Input!Y15="Blue",1,0))*Input!R15 -> 0 | M9: =(IF(Input!L15="White",1,0)+IF(Input!M15="White",1,0)+IF(Input!N15="White",1,0)+IF(Input!O15="White",1,0)+IF(Input!P15="White",1,0))*Input!I15+(IF(Input!U15="White",1,0)+IF(Input!V15="White",1,0)+IF(Input!W15="White",1,0)+IF(Input!X15="White",1,0)+IF(Input!Y15="White",1,0))*Input!R15 -> 0 | N9: =(IF(Input!L15="Black",1,0)+IF(Input!M15="Black",1,0)+IF(Input!N15="Black",1,0)+IF(Input!O15="Black",1,0)+IF(Input!P15="Black",1,0))*Input!I15+(IF(Input!U15="Black",1,0)+IF(Input!V15="Black",1,0)+IF(Input!W15="Black",1,0)+IF(Input!X15="Black",1,0)+IF(Input!Y15="Black",1,0))*Input!R15 -> 0 | O9: =(IF(Input!L15="Colorless",1,0)+IF(Input!M15="Colorless",1,0)+IF(Input!N15="Colorless",1,0)+IF(Input!O15="Colorless",1,0)+IF(Input!P15="Colorless",1,0))*Input!I15+(IF(Input!U15="Colorless",1,0)+IF(Input!V15="Colorless",1,0)+IF(Input!W15="Colorless",1,0)+IF(Input!X15="Colorless",1,0)+IF(Input!Y15="Colorless",1,0))*Input!R15 -> 0 | Q9: =(IF(Input!Q15="Sorcery",1,0))*Input!I15+(IF(Input!Z15="Sorcery",1,0))*Input!R15 -> 0 | R9: =(IF(Input!Q15="Instant",1,0))*Input!I15+(IF(Input!Z15="Instant",1,0))*Input!R15 -> 0 | S9: =(IF(Input!Q15="Artifact",1,0))*Input!I15+(IF(Input!Z15="Artifact",1,0))*Input!R15 -> 0 | T9: =(IF(Input!Q15="Enchantment",1,0))*Input!I15+(IF(Input!Z15="Enchantment",1,0))*Input!R15 -> 0 | U9: =(IF(Input!Q15="Creature",1,0))*Input!I15+(IF(Input!Z15="Creature",1,0))*Input!R15 -> 0 | V9: =(IF(Input!Q15="Planeswalker",1,0))*Input!I15+(IF(Input!Z15="Planeswalker",1,0))*Input!R15 -> 0 | AF9: =IF(Input!K15=0,1,0)*Input!I15+IF(Input!T15=0,1,0)*Input!R15 -> 0 | AG9: =IF(Input!K15=1,1,0)*Input!I15+IF(Input!T15=1,1,0)*Input!R15 -> 0 | AH9: =IF(Input!K15=2,1,0)*Input!I15+IF(Input!T15=2,1,0)*Input!R15 -> 0 | AI9: =IF(Input!K15=3,1,0)*Input!I16+IF(Input!T15=3,1,0)*Input!R15 -> 0 | AJ9: =IF(Input!K15=4,1,0)*Input!I15+IF(Input!T15=4,1,0)*Input!R15 -> 0 | AK9: =IF(Input!K15=5,1,0)*Input!I15+IF(Input!T15=5,1,0)*Input!R15 -> 0 | AL9: =IF(Input!K15=6,1,0)*Input!I15+IF(Input!T15=6,1,0)*Input!R15 -> 0 | AM9: =IF(Input!K15=7,1,0)*Input!I15+IF(Input!T15=7,1,0)*Input!R15 -> 0 | AN9: =IF(Input!K15=8,1,0)*Input!I15+IF(Input!T15=8,1,0)*Input!R15 -> 0 | AO9: =IF(Input!K15=9,1,0)*Input!I15+IF(Input!T15=9,1,0)*Input!R15 -> 0 | AP9: =IF(Input!K15=10,1,0)*Input!I15+IF(Input!T15=10,1,0)*Input!R15 -> 0 | AQ9: =IF(Input!K15=11,1,0)*Input!I15+IF(Input!T15=11,1,0)*Input!R15 -> 0 | AR9: =IF(Input!K15=12,1,0)*Input!I15+IF(Input!T15=12,1,0)*Input!R15 -> 0 | AS9: =IF(Input!K15=13,1,0)*Input!I15+IF(Input!T15=13,1,0)*Input!R15 -> 0 | AT9: =IF(Input!K15=14,1,0)*Input!I15+IF(Input!T15=14,1,0)*Input!R15 -> 0 | AU9: =IF(Input!K15=15,1,0)*Input!I15+IF(Input!T15=15,1,0)*Input!R15 -> 0 | AV9: =IF(Input!K15=16,1,0)*Input!I15+IF(Input!T15=16,1,0)*Input!R15 -> 0
B10: =(IF(Input!C16="Green",1,0)+IF(Input!D16="Green",1,0)+IF(Input!E16="Green",1,0)+IF(Input!F16="Green",1,0)+IF(Input!G16="Green",1,0)+IF(Input!H16="Green",1,0))*Input!A16 -> 0 | C10: =(IF(Input!C16="Red",1,0)+IF(Input!D16="Red",1,0)+IF(Input!E16="Red",1,0)+IF(Input!F16="Red",1,0)+IF(Input!G16="Red",1,0)+IF(Input!H16="Red",1,0))*Input!A16 -> 0 | D10: =(IF(Input!C16="Blue",1,0)+IF(Input!D16="Blue",1,0)+IF(Input!E16="Blue",1,0)+IF(Input!F16="Blue",1,0)+IF(Input!G16="Blue",1,0)+IF(Input!H16="Blue",1,0))*Input!A16 -> 0 | E10: =(IF(Input!C16="White",1,0)+IF(Input!D16="White",1,0)+IF(Input!E16="White",1,0)+IF(Input!F16="White",1,0)+IF(Input!G16="White",1,0)+IF(Input!H16="White",1,0))*Input!A16 -> 0 | F10: =(IF(Input!C16="Black",1,0)+IF(Input!D16="Black",1,0)+IF(Input!E16="Black",1,0)+IF(Input!F16="Black",1,0)+IF(Input!G16="Black",1,0)+IF(Input!H16="Black",1,0))*Input!A16 -> 0 | G10: =(IF(Input!C16="Colorless",1,0)+IF(Input!D16="Colorless",1,0)+IF(Input!E16="Colorless",1,0)+IF(Input!F16="Colorless",1,0)+IF(Input!G16="Colorless",1,0)+IF(Input!H16="Colorless",1,0))*Input!A16 -> 0 | J10: =(IF(Input!L16="Green",1,0)+IF(Input!M16="Green",1,0)+IF(Input!N16="Green",1,0)+IF(Input!O16="Green",1,0)+IF(Input!P16="Green",1,0))*Input!I16+(IF(Input!U16="Green",1,0)+IF(Input!V16="Green",1,0)+IF(Input!W16="Green",1,0)+IF(Input!X16="Green",1,0)+IF(Input!Y16="Green",1,0))*Input!R16 -> 0 | K10: =(IF(Input!L16="Red",1,0)+IF(Input!M16="Red",1,0)+IF(Input!N16="Red",1,0)+IF(Input!O16="Red",1,0)+IF(Input!P16="Red",1,0))*Input!I16+(IF(Input!U16="Red",1,0)+IF(Input!V16="Red",1,0)+IF(Input!W16="Red",1,0)+IF(Input!X16="Red",1,0)+IF(Input!Y16="Red",1,0))*Input!R16 -> 0 | L10: =(IF(Input!L16="Blue",1,0)+IF(Input!M16="Blue",1,0)+IF(Input!N16="Blue",1,0)+IF(Input!O16="Blue",1,0)+IF(Input!P16="Blue",1,0))*Input!I16+(IF(Input!U16="Blue",1,0)+IF(Input!V16="Blue",1,0)+IF(Input!W16="Blue",1,0)+IF(Input!X16="Blue",1,0)+IF(Input!Y16="Blue",1,0))*Input!R16 -> 0 | M10: =(IF(Input!L16="White",1,0)+IF(Input!M16="White",1,0)+IF(Input!N16="White",1,0)+IF(Input!O16="White",1,0)+IF(Input!P16="White",1,0))*Input!I16+(IF(Input!U16="White",1,0)+IF(Input!V16="White",1,0)+IF(Input!W16="White",1,0)+IF(Input!X16="White",1,0)+IF(Input!Y16="White",1,0))*Input!R16 -> 0 | N10: =(IF(Input!L16="Black",1,0)+IF(Input!M16="Black",1,0)+IF(Input!N16="Black",1,0)+IF(Input!O16="Black",1,0)+IF(Input!P16="Black",1,0))*Input!I16+(IF(Input!U16="Black",1,0)+IF(Input!V16="Black",1,0)+IF(Input!W16="Black",1,0)+IF(Input!X16="Black",1,0)+IF(Input!Y16="Black",1,0))*Input!R16 -> 0 | O10: =(IF(Input!L16="Colorless",1,0)+IF(Input!M16="Colorless",1,0)+IF(Input!N16="Colorless",1,0)+IF(Input!O16="Colorless",1,0)+IF(Input!P16="Colorless",1,0))*Input!I16+(IF(Input!U16="Colorless",1,0)+IF(Input!V16="Colorless",1,0)+IF(Input!W16="Colorless",1,0)+IF(Input!X16="Colorless",1,0)+IF(Input!Y16="Colorless",1,0))*Input!R16 -> 0 | Q10: =(IF(Input!Q16="Sorcery",1,0))*Input!I16+(IF(Input!Z16="Sorcery",1,0))*Input!R16 -> 0 | R10: =(IF(Input!Q16="Instant",1,0))*Input!I16+(IF(Input!Z16="Instant",1,0))*Input!R16 -> 0 | S10: =(IF(Input!Q16="Artifact",1,0))*Input!I16+(IF(Input!Z16="Artifact",1,0))*Input!R16 -> 0 | T10: =(IF(Input!Q16="Enchantment",1,0))*Input!I16+(IF(Input!Z16="Enchantment",1,0))*Input!R16 -> 0 | U10: =(IF(Input!Q16="Creature",1,0))*Input!I16+(IF(Input!Z16="Creature",1,0))*Input!R16 -> 0 | V10: =(IF(Input!Q16="Planeswalker",1,0))*Input!I16+(IF(Input!Z16="Planeswalker",1,0))*Input!R16 -> 0 | AF10: =IF(Input!K16=0,1,0)*Input!I16+IF(Input!T16=0,1,0)*Input!R16 -> 0 | AG10: =IF(Input!K16=1,1,0)*Input!I16+IF(Input!T16=1,1,0)*Input!R16 -> 0 | AH10: =IF(Input!K16=2,1,0)*Input!I16+IF(Input!T16=2,1,0)*Input!R16 -> 0 | AI10: =IF(Input!K16=3,1,0)*Input!I17+IF(Input!T16=3,1,0)*Input!R16 -> 0 | AJ10: =IF(Input!K16=4,1,0)*Input!I16+IF(Input!T16=4,1,0)*Input!R16 -> 0 | AK10: =IF(Input!K16=5,1,0)*Input!I16+IF(Input!T16=5,1,0)*Input!R16 -> 0 | AL10: =IF(Input!K16=6,1,0)*Input!I16+IF(Input!T16=6,1,0)*Input!R16 -> 0 | AM10: =IF(Input!K16=7,1,0)*Input!I16+IF(Input!T16=7,1,0)*Input!R16 -> 0 | AN10: =IF(Input!K16=8,1,0)*Input!I16+IF(Input!T16=8,1,0)*Input!R16 -> 0 | AO10: =IF(Input!K16=9,1,0)*Input!I16+IF(Input!T16=9,1,0)*Input!R16 -> 0 | AP10: =IF(Input!K16=10,1,0)*Input!I16+IF(Input!T16=10,1,0)*Input!R16 -> 0 | AQ10: =IF(Input!K16=11,1,0)*Input!I16+IF(Input!T16=11,1,0)*Input!R16 -> 0 | AR10: =IF(Input!K16=12,1,0)*Input!I16+IF(Input!T16=12,1,0)*Input!R16 -> 0 | AS10: =IF(Input!K16=13,1,0)*Input!I16+IF(Input!T16=13,1,0)*Input!R16 -> 0 | AT10: =IF(Input!K16=14,1,0)*Input!I16+IF(Input!T16=14,1,0)*Input!R16 -> 0 | AU10: =IF(Input!K16=15,1,0)*Input!I16+IF(Input!T16=15,1,0)*Input!R16 -> 0 | AV10: =IF(Input!K16=16,1,0)*Input!I16+IF(Input!T16=16,1,0)*Input!R16 -> 0
B11: =(IF(Input!C17="Green",1,0)+IF(Input!D17="Green",1,0)+IF(Input!E17="Green",1,0)+IF(Input!F17="Green",1,0)+IF(Input!G17="Green",1,0)+IF(Input!H17="Green",1,0))*Input!A17 -> 0 | C11: =(IF(Input!C17="Red",1,0)+IF(Input!D17="Red",1,0)+IF(Input!E17="Red",1,0)+IF(Input!F17="Red",1,0)+IF(Input!G17="Red",1,0)+IF(Input!H17="Red",1,0))*Input!A17 -> 0 | D11: =(IF(Input!C17="Blue",1,0)+IF(Input!D17="Blue",1,0)+IF(Input!E17="Blue",1,0)+IF(Input!F17="Blue",1,0)+IF(Input!G17="Blue",1,0)+IF(Input!H17="Blue",1,0))*Input!A17 -> 0 | E11: =(IF(Input!C17="White",1,0)+IF(Input!D17="White",1,0)+IF(Input!E17="White",1,0)+IF(Input!F17="White",1,0)+IF(Input!G17="White",1,0)+IF(Input!H17="White",1,0))*Input!A17 -> 0 | F11: =(IF(Input!C17="Black",1,0)+IF(Input!D17="Black",1,0)+IF(Input!E17="Black",1,0)+IF(Input!F17="Black",1,0)+IF(Input!G17="Black",1,0)+IF(Input!H17="Black",1,0))*Input!A17 -> 0 | G11: =(IF(Input!C17="Colorless",1,0)+IF(Input!D17="Colorless",1,0)+IF(Input!E17="Colorless",1,0)+IF(Input!F17="Colorless",1,0)+IF(Input!G17="Colorless",1,0)+IF(Input!H17="Colorless",1,0))*Input!A17 -> 0 | J11: =(IF(Input!L17="Green",1,0)+IF(Input!M17="Green",1,0)+IF(Input!N17="Green",1,0)+IF(Input!O17="Green",1,0)+IF(Input!P17="Green",1,0))*Input!I17+(IF(Input!U17="Green",1,0)+IF(Input!V17="Green",1,0)+IF(Input!W17="Green",1,0)+IF(Input!X17="Green",1,0)+IF(Input!Y17="Green",1,0))*Input!R17 -> 0 | K11: =(IF(Input!L17="Red",1,0)+IF(Input!M17="Red",1,0)+IF(Input!N17="Red",1,0)+IF(Input!O17="Red",1,0)+IF(Input!P17="Red",1,0))*Input!I17+(IF(Input!U17="Red",1,0)+IF(Input!V17="Red",1,0)+IF(Input!W17="Red",1,0)+IF(Input!X17="Red",1,0)+IF(Input!Y17="Red",1,0))*Input!R17 -> 0 | L11: =(IF(Input!L17="Blue",1,0)+IF(Input!M17="Blue",1,0)+IF(Input!N17="Blue",1,0)+IF(Input!O17="Blue",1,0)+IF(Input!P17="Blue",1,0))*Input!I17+(IF(Input!U17="Blue",1,0)+IF(Input!V17="Blue",1,0)+IF(Input!W17="Blue",1,0)+IF(Input!X17="Blue",1,0)+IF(Input!Y17="Blue",1,0))*Input!R17 -> 0 | M11: =(IF(Input!L17="White",1,0)+IF(Input!M17="White",1,0)+IF(Input!N17="White",1,0)+IF(Input!O17="White",1,0)+IF(Input!P17="White",1,0))*Input!I17+(IF(Input!U17="White",1,0)+IF(Input!V17="White",1,0)+IF(Input!W17="White",1,0)+IF(Input!X17="White",1,0)+IF(Input!Y17="White",1,0))*Input!R17 -> 0 | N11: =(IF(Input!L17="Black",1,0)+IF(Input!M17="Black",1,0)+IF(Input!N17="Black",1,0)+IF(Input!O17="Black",1,0)+IF(Input!P17="Black",1,0))*Input!I17+(IF(Input!U17="Black",1,0)+IF(Input!V17="Black",1,0)+IF(Input!W17="Black",1,0)+IF(Input!X17="Black",1,0)+IF(Input!Y17="Black",1,0))*Input!R17 -> 0 | O11: =(IF(Input!L17="Colorless",1,0)+IF(Input!M17="Colorless",1,0)+IF(Input!N17="Colorless",1,0)+IF(Input!O17="Colorless",1,0)+IF(Input!P17="Colorless",1,0))*Input!I17+(IF(Input!U17="Colorless",1,0)+IF(Input!V17="Colorless",1,0)+IF(Input!W17="Colorless",1,0)+IF(Input!X17="Colorless",1,0)+IF(Input!Y17="Colorless",1,0))*Input!R17 -> 0 | Q11: =(IF(Input!Q17="Sorcery",1,0))*Input!I17+(IF(Input!Z17="Sorcery",1,0))*Input!R17 -> 0 | R11: =(IF(Input!Q17="Instant",1,0))*Input!I17+(IF(Input!Z17="Instant",1,0))*Input!R17 -> 0 | S11: =(IF(Input!Q17="Artifact",1,0))*Input!I17+(IF(Input!Z17="Artifact",1,0))*Input!R17 -> 0 | T11: =(IF(Input!Q17="Enchantment",1,0))*Input!I17+(IF(Input!Z17="Enchantment",1,0))*Input!R17 -> 0 | U11: =(IF(Input!Q17="Creature",1,0))*Input!I17+(IF(Input!Z17="Creature",1,0))*Input!R17 -> 0 | V11: =(IF(Input!Q17="Planeswalker",1,0))*Input!I17+(IF(Input!Z17="Planeswalker",1,0))*Input!R17 -> 0 | AF11: =IF(Input!K17=0,1,0)*Input!I17+IF(Input!T17=0,1,0)*Input!R17 -> 0 | AG11: =IF(Input!K17=1,1,0)*Input!I17+IF(Input!T17=1,1,0)*Input!R17 -> 0 | AH11: =IF(Input!K17=2,1,0)*Input!I17+IF(Input!T17=2,1,0)*Input!R17 -> 0 | AI11: =IF(Input!K17=3,1,0)*Input!I18+IF(Input!T17=3,1,0)*Input!R17 -> 0 | AJ11: =IF(Input!K17=4,1,0)*Input!I17+IF(Input!T17=4,1,0)*Input!R17 -> 0 | AK11: =IF(Input!K17=5,1,0)*Input!I17+IF(Input!T17=5,1,0)*Input!R17 -> 0 | AL11: =IF(Input!K17=6,1,0)*Input!I17+IF(Input!T17=6,1,0)*Input!R17 -> 0 | AM11: =IF(Input!K17=7,1,0)*Input!I17+IF(Input!T17=7,1,0)*Input!R17 -> 0 | AN11: =IF(Input!K17=8,1,0)*Input!I17+IF(Input!T17=8,1,0)*Input!R17 -> 0 | AO11: =IF(Input!K17=9,1,0)*Input!I17+IF(Input!T17=9,1,0)*Input!R17 -> 0 | AP11: =IF(Input!K17=10,1,0)*Input!I17+IF(Input!T17=10,1,0)*Input!R17 -> 0 | AQ11: =IF(Input!K17=11,1,0)*Input!I17+IF(Input!T17=11,1,0)*Input!R17 -> 0 | AR11: =IF(Input!K17=12,1,0)*Input!I17+IF(Input!T17=12,1,0)*Input!R17 -> 0 | AS11: =IF(Input!K17=13,1,0)*Input!I17+IF(Input!T17=13,1,0)*Input!R17 -> 0 | AT11: =IF(Input!K17=14,1,0)*Input!I17+IF(Input!T17=14,1,0)*Input!R17 -> 0 | AU11: =IF(Input!K17=15,1,0)*Input!I17+IF(Input!T17=15,1,0)*Input!R17 -> 0 | AV11: =IF(Input!K17=16,1,0)*Input!I17+IF(Input!T17=16,1,0)*Input!R17 -> 0
B12: =(IF(Input!C18="Green",1,0)+IF(Input!D18="Green",1,0)+IF(Input!E18="Green",1,0)+IF(Input!F18="Green",1,0)+IF(Input!G18="Green",1,0)+IF(Input!H18="Green",1,0))*Input!A18 -> 0 | C12: =(IF(Input!C18="Red",1,0)+IF(Input!D18="Red",1,0)+IF(Input!E18="Red",1,0)+IF(Input!F18="Red",1,0)+IF(Input!G18="Red",1,0)+IF(Input!H18="Red",1,0))*Input!A18 -> 0 | D12: =(IF(Input!C18="Blue",1,0)+IF(Input!D18="Blue",1,0)+IF(Input!E18="Blue",1,0)+IF(Input!F18="Blue",1,0)+IF(Input!G18="Blue",1,0)+IF(Input!H18="Blue",1,0))*Input!A18 -> 0 | E12: =(IF(Input!C18="White",1,0)+IF(Input!D18="White",1,0)+IF(Input!E18="White",1,0)+IF(Input!F18="White",1,0)+IF(Input!G18="White",1,0)+IF(Input!H18="White",1,0))*Input!A18 -> 0 | F12: =(IF(Input!C18="Black",1,0)+IF(Input!D18="Black",1,0)+IF(Input!E18="Black",1,0)+IF(Input!F18="Black",1,0)+IF(Input!G18="Black",1,0)+IF(Input!H18="Black",1,0))*Input!A18 -> 0 | G12: =(IF(Input!C18="Colorless",1,0)+IF(Input!D18="Colorless",1,0)+IF(Input!E18="Colorless",1,0)+IF(Input!F18="Colorless",1,0)+IF(Input!G18="Colorless",1,0)+IF(Input!H18="Colorless",1,0))*Input!A18 -> 0 | J12: =(IF(Input!L18="Green",1,0)+IF(Input!M18="Green",1,0)+IF(Input!N18="Green",1,0)+IF(Input!O18="Green",1,0)+IF(Input!P18="Green",1,0))*Input!I18+(IF(Input!U18="Green",1,0)+IF(Input!V18="Green",1,0)+IF(Input!W18="Green",1,0)+IF(Input!X18="Green",1,0)+IF(Input!Y18="Green",1,0))*Input!R18 -> 0 | K12: =(IF(Input!L18="Red",1,0)+IF(Input!M18="Red",1,0)+IF(Input!N18="Red",1,0)+IF(Input!O18="Red",1,0)+IF(Input!P18="Red",1,0))*Input!I18+(IF(Input!U18="Red",1,0)+IF(Input!V18="Red",1,0)+IF(Input!W18="Red",1,0)+IF(Input!X18="Red",1,0)+IF(Input!Y18="Red",1,0))*Input!R18 -> 0 | L12: =(IF(Input!L18="Blue",1,0)+IF(Input!M18="Blue",1,0)+IF(Input!N18="Blue",1,0)+IF(Input!O18="Blue",1,0)+IF(Input!P18="Blue",1,0))*Input!I18+(IF(Input!U18="Blue",1,0)+IF(Input!V18="Blue",1,0)+IF(Input!W18="Blue",1,0)+IF(Input!X18="Blue",1,0)+IF(Input!Y18="Blue",1,0))*Input!R18 -> 0 | M12: =(IF(Input!L18="White",1,0)+IF(Input!M18="White",1,0)+IF(Input!N18="White",1,0)+IF(Input!O18="White",1,0)+IF(Input!P18="White",1,0))*Input!I18+(IF(Input!U18="White",1,0)+IF(Input!V18="White",1,0)+IF(Input!W18="White",1,0)+IF(Input!X18="White",1,0)+IF(Input!Y18="White",1,0))*Input!R18 -> 0 | N12: =(IF(Input!L18="Black",1,0)+IF(Input!M18="Black",1,0)+IF(Input!N18="Black",1,0)+IF(Input!O18="Black",1,0)+IF(Input!P18="Black",1,0))*Input!I18+(IF(Input!U18="Black",1,0)+IF(Input!V18="Black",1,0)+IF(Input!W18="Black",1,0)+IF(Input!X18="Black",1,0)+IF(Input!Y18="Black",1,0))*Input!R18 -> 0 | O12: =(IF(Input!L18="Colorless",1,0)+IF(Input!M18="Colorless",1,0)+IF(Input!N18="Colorless",1,0)+IF(Input!O18="Colorless",1,0)+IF(Input!P18="Colorless",1,0))*Input!I18+(IF(Input!U18="Colorless",1,0)+IF(Input!V18="Colorless",1,0)+IF(Input!W18="Colorless",1,0)+IF(Input!X18="Colorless",1,0)+IF(Input!Y18="Colorless",1,0))*Input!R18 -> 0 | Q12: =(IF(Input!Q18="Sorcery",1,0))*Input!I18+(IF(Input!Z18="Sorcery",1,0))*Input!R18 -> 0 | R12: =(IF(Input!Q18="Instant",1,0))*Input!I18+(IF(Input!Z18="Instant",1,0))*Input!R18 -> 0 | S12: =(IF(Input!Q18="Artifact",1,0))*Input!I18+(IF(Input!Z18="Artifact",1,0))*Input!R18 -> 0 | T12: =(IF(Input!Q18="Enchantment",1,0))*Input!I18+(IF(Input!Z18="Enchantment",1,0))*Input!R18 -> 0 | U12: =(IF(Input!Q18="Creature",1,0))*Input!I18+(IF(Input!Z18="Creature",1,0))*Input!R18 -> 0 | V12: =(IF(Input!Q18="Planeswalker",1,0))*Input!I18+(IF(Input!Z18="Planeswalker",1,0))*Input!R18 -> 0 | AF12: =IF(Input!K18=0,1,0)*Input!I18+IF(Input!T18=0,1,0)*Input!R18 -> 0 | AG12: =IF(Input!K18=1,1,0)*Input!I18+IF(Input!T18=1,1,0)*Input!R18 -> 0 | AH12: =IF(Input!K18=2,1,0)*Input!I18+IF(Input!T18=2,1,0)*Input!R18 -> 0 | AI12: =IF(Input!K18=3,1,0)*Input!I19+IF(Input!T18=3,1,0)*Input!R18 -> 0 | AJ12: =IF(Input!K18=4,1,0)*Input!I18+IF(Input!T18=4,1,0)*Input!R18 -> 0 | AK12: =IF(Input!K18=5,1,0)*Input!I18+IF(Input!T18=5,1,0)*Input!R18 -> 0 | AL12: =IF(Input!K18=6,1,0)*Input!I18+IF(Input!T18=6,1,0)*Input!R18 -> 0 | AM12: =IF(Input!K18=7,1,0)*Input!I18+IF(Input!T18=7,1,0)*Input!R18 -> 0 | AN12: =IF(Input!K18=8,1,0)*Input!I18+IF(Input!T18=8,1,0)*Input!R18 -> 0 | AO12: =IF(Input!K18=9,1,0)*Input!I18+IF(Input!T18=9,1,0)*Input!R18 -> 0 | AP12: =IF(Input!K18=10,1,0)*Input!I18+IF(Input!T18=10,1,0)*Input!R18 -> 0 | AQ12: =IF(Input!K18=11,1,0)*Input!I18+IF(Input!T18=11,1,0)*Input!R18 -> 0 | AR12: =IF(Input!K18=12,1,0)*Input!I18+IF(Input!T18=12,1,0)*Input!R18 -> 0 | AS12: =IF(Input!K18=13,1,0)*Input!I18+IF(Input!T18=13,1,0)*Input!R18 -> 0 | AT12: =IF(Input!K18=14,1,0)*Input!I18+IF(Input!T18=14,1,0)*Input!R18 -> 0 | AU12: =IF(Input!K18=15,1,0)*Input!I18+IF(Input!T18=15,1,0)*Input!R18 -> 0 | AV12: =IF(Input!K18=16,1,0)*Input!I18+IF(Input!T18=16,1,0)*Input!R18 -> 0
B13: =(IF(Input!C19="Green",1,0)+IF(Input!D19="Green",1,0)+IF(Input!E19="Green",1,0)+IF(Input!F19="Green",1,0)+IF(Input!G19="Green",1,0)+IF(Input!H19="Green",1,0))*Input!A19 -> 0 | C13: =(IF(Input!C19="Red",1,0)+IF(Input!D19="Red",1,0)+IF(Input!E19="Red",1,0)+IF(Input!F19="Red",1,0)+IF(Input!G19="Red",1,0)+IF(Input!H19="Red",1,0))*Input!A19 -> 0 | D13: =(IF(Input!C19="Blue",1,0)+IF(Input!D19="Blue",1,0)+IF(Input!E19="Blue",1,0)+IF(Input!F19="Blue",1,0)+IF(Input!G19="Blue",1,0)+IF(Input!H19="Blue",1,0))*Input!A19 -> 0 | E13: =(IF(Input!C19="White",1,0)+IF(Input!D19="White",1,0)+IF(Input!E19="White",1,0)+IF(Input!F19="White",1,0)+IF(Input!G19="White",1,0)+IF(Input!H19="White",1,0))*Input!A19 -> 0 | F13: =(IF(Input!C19="Black",1,0)+IF(Input!D19="Black",1,0)+IF(Input!E19="Black",1,0)+IF(Input!F19="Black",1,0)+IF(Input!G19="Black",1,0)+IF(Input!H19="Black",1,0))*Input!A19 -> 0 | G13: =(IF(Input!C19="Colorless",1,0)+IF(Input!D19="Colorless",1,0)+IF(Input!E19="Colorless",1,0)+IF(Input!F19="Colorless",1,0)+IF(Input!G19="Colorless",1,0)+IF(Input!H19="Colorless",1,0))*Input!A19 -> 0 | J13: =(IF(Input!L19="Green",1,0)+IF(Input!M19="Green",1,0)+IF(Input!N19="Green",1,0)+IF(Input!O19="Green",1,0)+IF(Input!P19="Green",1,0))*Input!I19+(IF(Input!U19="Green",1,0)+IF(Input!V19="Green",1,0)+IF(Input!W19="Green",1,0)+IF(Input!X19="Green",1,0)+IF(Input!Y19="Green",1,0))*Input!R19 -> 0 | K13: =(IF(Input!L19="Red",1,0)+IF(Input!M19="Red",1,0)+IF(Input!N19="Red",1,0)+IF(Input!O19="Red",1,0)+IF(Input!P19="Red",1,0))*Input!I19+(IF(Input!U19="Red",1,0)+IF(Input!V19="Red",1,0)+IF(Input!W19="Red",1,0)+IF(Input!X19="Red",1,0)+IF(Input!Y19="Red",1,0))*Input!R19 -> 0 | L13: =(IF(Input!L19="Blue",1,0)+IF(Input!M19="Blue",1,0)+IF(Input!N19="Blue",1,0)+IF(Input!O19="Blue",1,0)+IF(Input!P19="Blue",1,0))*Input!I19+(IF(Input!U19="Blue",1,0)+IF(Input!V19="Blue",1,0)+IF(Input!W19="Blue",1,0)+IF(Input!X19="Blue",1,0)+IF(Input!Y19="Blue",1,0))*Input!R19 -> 0 | M13: =(IF(Input!L19="White",1,0)+IF(Input!M19="White",1,0)+IF(Input!N19="White",1,0)+IF(Input!O19="White",1,0)+IF(Input!P19="White",1,0))*Input!I19+(IF(Input!U19="White",1,0)+IF(Input!V19="White",1,0)+IF(Input!W19="White",1,0)+IF(Input!X19="White",1,0)+IF(Input!Y19="White",1,0))*Input!R19 -> 0 | N13: =(IF(Input!L19="Black",1,0)+IF(Input!M19="Black",1,0)+IF(Input!N19="Black",1,0)+IF(Input!O19="Black",1,0)+IF(Input!P19="Black",1,0))*Input!I19+(IF(Input!U19="Black",1,0)+IF(Input!V19="Black",1,0)+IF(Input!W19="Black",1,0)+IF(Input!X19="Black",1,0)+IF(Input!Y19="Black",1,0))*Input!R19 -> 0 | O13: =(IF(Input!L19="Colorless",1,0)+IF(Input!M19="Colorless",1,0)+IF(Input!N19="Colorless",1,0)+IF(Input!O19="Colorless",1,0)+IF(Input!P19="Colorless",1,0))*Input!I19+(IF(Input!U19="Colorless",1,0)+IF(Input!V19="Colorless",1,0)+IF(Input!W19="Colorless",1,0)+IF(Input!X19="Colorless",1,0)+IF(Input!Y19="Colorless",1,0))*Input!R19 -> 0 | Q13: =(IF(Input!Q19="Sorcery",1,0))*Input!I19+(IF(Input!Z19="Sorcery",1,0))*Input!R19 -> 0 | R13: =(IF(Input!Q19="Instant",1,0))*Input!I19+(IF(Input!Z19="Instant",1,0))*Input!R19 -> 0 | S13: =(IF(Input!Q19="Artifact",1,0))*Input!I19+(IF(Input!Z19="Artifact",1,0))*Input!R19 -> 0 | T13: =(IF(Input!Q19="Enchantment",1,0))*Input!I19+(IF(Input!Z19="Enchantment",1,0))*Input!R19 -> 0 | U13: =(IF(Input!Q19="Creature",1,0))*Input!I19+(IF(Input!Z19="Creature",1,0))*Input!R19 -> 0 | V13: =(IF(Input!Q19="Planeswalker",1,0))*Input!I19+(IF(Input!Z19="Planeswalker",1,0))*Input!R19 -> 0 | AF13: =IF(Input!K19=0,1,0)*Input!I19+IF(Input!T19=0,1,0)*Input!R19 -> 0 | AG13: =IF(Input!K19=1,1,0)*Input!I19+IF(Input!T19=1,1,0)*Input!R19 -> 0 | AH13: =IF(Input!K19=2,1,0)*Input!I19+IF(Input!T19=2,1,0)*Input!R19 -> 0 | AI13: =IF(Input!K19=3,1,0)*Input!I20+IF(Input!T19=3,1,0)*Input!R19 -> 0 | AJ13: =IF(Input!K19=4,1,0)*Input!I19+IF(Input!T19=4,1,0)*Input!R19 -> 0 | AK13: =IF(Input!K19=5,1,0)*Input!I19+IF(Input!T19=5,1,0)*Input!R19 -> 0 | AL13: =IF(Input!K19=6,1,0)*Input!I19+IF(Input!T19=6,1,0)*Input!R19 -> 0 | AM13: =IF(Input!K19=7,1,0)*Input!I19+IF(Input!T19=7,1,0)*Input!R19 -> 0 | AN13: =IF(Input!K19=8,1,0)*Input!I19+IF(Input!T19=8,1,0)*Input!R19 -> 0 | AO13: =IF(Input!K19=9,1,0)*Input!I19+IF(Input!T19=9,1,0)*Input!R19 -> 0 | AP13: =IF(Input!K19=10,1,0)*Input!I19+IF(Input!T19=10,1,0)*Input!R19 -> 0 | AQ13: =IF(Input!K19=11,1,0)*Input!I19+IF(Input!T19=11,1,0)*Input!R19 -> 0 | AR13: =IF(Input!K19=12,1,0)*Input!I19+IF(Input!T19=12,1,0)*Input!R19 -> 0 | AS13: =IF(Input!K19=13,1,0)*Input!I19+IF(Input!T19=13,1,0)*Input!R19 -> 0 | AT13: =IF(Input!K19=14,1,0)*Input!I19+IF(Input!T19=14,1,0)*Input!R19 -> 0 | AU13: =IF(Input!K19=15,1,0)*Input!I19+IF(Input!T19=15,1,0)*Input!R19 -> 0 | AV13: =IF(Input!K19=16,1,0)*Input!I19+IF(Input!T19=16,1,0)*Input!R19 -> 0
B14: =(IF(Input!C20="Green",1,0)+IF(Input!D20="Green",1,0)+IF(Input!E20="Green",1,0)+IF(Input!F20="Green",1,0)+IF(Input!G20="Green",1,0)+IF(Input!H20="Green",1,0))*Input!A20 -> 0 | C14: =(IF(Input!C20="Red",1,0)+IF(Input!D20="Red",1,0)+IF(Input!E20="Red",1,0)+IF(Input!F20="Red",1,0)+IF(Input!G20="Red",1,0)+IF(Input!H20="Red",1,0))*Input!A20 -> 0 | D14: =(IF(Input!C20="Blue",1,0)+IF(Input!D20="Blue",1,0)+IF(Input!E20="Blue",1,0)+IF(Input!F20="Blue",1,0)+IF(Input!G20="Blue",1,0)+IF(Input!H20="Blue",1,0))*Input!A20 -> 0 | E14: =(IF(Input!C20="White",1,0)+IF(Input!D20="White",1,0)+IF(Input!E20="White",1,0)+IF(Input!F20="White",1,0)+IF(Input!G20="White",1,0)+IF(Input!H20="White",1,0))*Input!A20 -> 0 | F14: =(IF(Input!C20="Black",1,0)+IF(Input!D20="Black",1,0)+IF(Input!E20="Black",1,0)+IF(Input!F20="Black",1,0)+IF(Input!G20="Black",1,0)+IF(Input!H20="Black",1,0))*Input!A20 -> 0 | G14: =(IF(Input!C20="Colorless",1,0)+IF(Input!D20="Colorless",1,0)+IF(Input!E20="Colorless",1,0)+IF(Input!F20="Colorless",1,0)+IF(Input!G20="Colorless",1,0)+IF(Input!H20="Colorless",1,0))*Input!A20 -> 0 | J14: =(IF(Input!L20="Green",1,0)+IF(Input!M20="Green",1,0)+IF(Input!N20="Green",1,0)+IF(Input!O20="Green",1,0)+IF(Input!P20="Green",1,0))*Input!I20+(IF(Input!U20="Green",1,0)+IF(Input!V20="Green",1,0)+IF(Input!W20="Green",1,0)+IF(Input!X20="Green",1,0)+IF(Input!Y20="Green",1,0))*Input!R20 -> 0 | K14: =(IF(Input!L20="Red",1,0)+IF(Input!M20="Red",1,0)+IF(Input!N20="Red",1,0)+IF(Input!O20="Red",1,0)+IF(Input!P20="Red",1,0))*Input!I20+(IF(Input!U20="Red",1,0)+IF(Input!V20="Red",1,0)+IF(Input!W20="Red",1,0)+IF(Input!X20="Red",1,0)+IF(Input!Y20="Red",1,0))*Input!R20 -> 0 | L14: =(IF(Input!L20="Blue",1,0)+IF(Input!M20="Blue",1,0)+IF(Input!N20="Blue",1,0)+IF(Input!O20="Blue",1,0)+IF(Input!P20="Blue",1,0))*Input!I20+(IF(Input!U20="Blue",1,0)+IF(Input!V20="Blue",1,0)+IF(Input!W20="Blue",1,0)+IF(Input!X20="Blue",1,0)+IF(Input!Y20="Blue",1,0))*Input!R20 -> 0 | M14: =(IF(Input!L20="White",1,0)+IF(Input!M20="White",1,0)+IF(Input!N20="White",1,0)+IF(Input!O20="White",1,0)+IF(Input!P20="White",1,0))*Input!I20+(IF(Input!U20="White",1,0)+IF(Input!V20="White",1,0)+IF(Input!W20="White",1,0)+IF(Input!X20="White",1,0)+IF(Input!Y20="White",1,0))*Input!R20 -> 0 | N14: =(IF(Input!L20="Black",1,0)+IF(Input!M20="Black",1,0)+IF(Input!N20="Black",1,0)+IF(Input!O20="Black",1,0)+IF(Input!P20="Black",1,0))*Input!I20+(IF(Input!U20="Black",1,0)+IF(Input!V20="Black",1,0)+IF(Input!W20="Black",1,0)+IF(Input!X20="Black",1,0)+IF(Input!Y20="Black",1,0))*Input!R20 -> 0 | O14: =(IF(Input!L20="Colorless",1,0)+IF(Input!M20="Colorless",1,0)+IF(Input!N20="Colorless",1,0)+IF(Input!O20="Colorless",1,0)+IF(Input!P20="Colorless",1,0))*Input!I20+(IF(Input!U20="Colorless",1,0)+IF(Input!V20="Colorless",1,0)+IF(Input!W20="Colorless",1,0)+IF(Input!X20="Colorless",1,0)+IF(Input!Y20="Colorless",1,0))*Input!R20 -> 0 | Q14: =(IF(Input!Q20="Sorcery",1,0))*Input!I20+(IF(Input!Z20="Sorcery",1,0))*Input!R20 -> 0 | R14: =(IF(Input!Q20="Instant",1,0))*Input!I20+(IF(Input!Z20="Instant",1,0))*Input!R20 -> 0 | S14: =(IF(Input!Q20="Artifact",1,0))*Input!I20+(IF(Input!Z20="Artifact",1,0))*Input!R20 -> 0 | T14: =(IF(Input!Q20="Enchantment",1,0))*Input!I20+(IF(Input!Z20="Enchantment",1,0))*Input!R20 -> 0 | U14: =(IF(Input!Q20="Creature",1,0))*Input!I20+(IF(Input!Z20="Creature",1,0))*Input!R20 -> 0 | V14: =(IF(Input!Q20="Planeswalker",1,0))*Input!I20+(IF(Input!Z20="Planeswalker",1,0))*Input!R20 -> 0 | AF14: =IF(Input!K20=0,1,0)*Input!I20+IF(Input!T20=0,1,0)*Input!R20 -> 0 | AG14: =IF(Input!K20=1,1,0)*Input!I20+IF(Input!T20=1,1,0)*Input!R20 -> 0 | AH14: =IF(Input!K20=2,1,0)*Input!I20+IF(Input!T20=2,1,0)*Input!R20 -> 0 | AI14: =IF(Input!K20=3,1,0)*Input!I21+IF(Input!T20=3,1,0)*Input!R20 -> 0 | AJ14: =IF(Input!K20=4,1,0)*Input!I20+IF(Input!T20=4,1,0)*Input!R20 -> 0 | AK14: =IF(Input!K20=5,1,0)*Input!I20+IF(Input!T20=5,1,0)*Input!R20 -> 0 | AL14: =IF(Input!K20=6,1,0)*Input!I20+IF(Input!T20=6,1,0)*Input!R20 -> 0 | AM14: =IF(Input!K20=7,1,0)*Input!I20+IF(Input!T20=7,1,0)*Input!R20 -> 0 | AN14: =IF(Input!K20=8,1,0)*Input!I20+IF(Input!T20=8,1,0)*Input!R20 -> 0 | AO14: =IF(Input!K20=9,1,0)*Input!I20+IF(Input!T20=9,1,0)*Input!R20 -> 0 | AP14: =IF(Input!K20=10,1,0)*Input!I20+IF(Input!T20=10,1,0)*Input!R20 -> 0 | AQ14: =IF(Input!K20=11,1,0)*Input!I20+IF(Input!T20=11,1,0)*Input!R20 -> 0 | AR14: =IF(Input!K20=12,1,0)*Input!I20+IF(Input!T20=12,1,0)*Input!R20 -> 0 | AS14: =IF(Input!K20=13,1,0)*Input!I20+IF(Input!T20=13,1,0)*Input!R20 -> 0 | AT14: =IF(Input!K20=14,1,0)*Input!I20+IF(Input!T20=14,1,0)*Input!R20 -> 0 | AU14: =IF(Input!K20=15,1,0)*Input!I20+IF(Input!T20=15,1,0)*Input!R20 -> 0 | AV14: =IF(Input!K20=16,1,0)*Input!I20+IF(Input!T20=16,1,0)*Input!R20 -> 0
